version: "3.8"
services:
  redis-server:
    image: "redis/redis-stack-server:latest"
    volumes:
      - ./configurations/redis/data:/data
      - ./configurations/redis/conf:/conf
    ports:
      - "127.0.0.1:6379:6379"
    entrypoint: redis-server
    command: /conf/redis.conf
  fluentd-server:
    image: "fluent/fluentd:edge-debian"
    ports:
      - "127.0.0.1:24224:24224"
    volumes:
      - ./configurations/fluentd/log:/fluentd/log
      - ./configurations/fluentd/conf:/fluentd/etc
  jupyter:
    image: "jupyter/datascience-notebook:ed2908bbb62e"
    volumes:
      - ./configurations/jupyter/conf:/conf
      - ./configurations/jupyter/notebooks:/home/jovyan/notebooks
      - ./redis-client:/home/jovyan/work
    ports:
      - "80:8888"
    environment:
      - ENVIRONMENT=development
      - TOKEN=${TOKEN}
    depends_on:
      - "redis-server"
    command: /conf/start.sh
  fastapi:
    image: "sage3/fastapi:arm64"
    ports:
      - "81:8000"
    environment:
      - ENVIRONMENT=development
      - SAGE3_SERVER=${HOST}
      - TOKEN=${TOKEN}
    restart: always
    working_dir: /app
    command: python src/main.py --url http://jupyter:80/
    depends_on:
      jupyter:
        condition: service_healthy
